# Google Cloud IoT


I get stuck with this error right now. Working on debugging this.

pi@MT-DataLogger:~/git/Google-Cloud-IoT $ python3 cloud_connect.py
{ "ts": 1553144292, "temperature": 31, "pressure": 13, "humidity": 7 }

on_connect 5: The connection was refused.